Workbook

Sheet GUIA
A1: BASE DE DATOS DEL DASHBOARD | B1: BD_dashboard_operaciones_github.xlsx
A2: Cómo usarla | B2: Edita únicamente las hojas de datos. El HTML toma la información de este archivo.
A3: Fechas de corte | B3: Cámbialas en CONFIG_HTML / CONFIG_DASHBOARD. Ej.: 22/09/2026.
A4: Nombres de columnas | B4: Puedes cambiar los nombres visibles en CONFIG_HTML o en la columna DISPLAY_NAME de ENCABEZADOS.
A5: Resumen Ejecutivo | B5: No se edita manualmente: el HTML lo calcula a partir de las demás hojas.
A6: Iniciativas Estratégicas | B6: Edita BD_INICIATIVAS. La pestaña Resumen reproduce la lógica de TD por estado y FECHA FIN PLANIFICADA.
A7: Estados permitidos | B7: EJECUTADO, EN PROCESO, PENDIENTE, CANCELADO.
A8: Campus | B8: Edita la lista en LISTAS si agregas o renombras campus.
A9: Importante | B9: No cambies los nombres de las hojas técnicas si quieres mantener la vinculación actual del HTML.
A10: MEJORAS_PROGRAMACION | B10: Tabla auxiliar para compatibilidad con el HTML; se genera a partir de BD_INICIATIVAS.

Sheet CONFIG_HTML
A1: selector | B1: tipo | C1: atributo | D1: valor | E1: descripcion
A2: meta:sec-resumen:eyebrow | B2: text | D2: Proyectos operacionales | E2: Etiqueta superior del Resumen Ejecutivo
A3: meta:sec-resumen:title | B3: text | D3: Resumen ejecutivo | E3: Título del Resumen Ejecutivo
A4: #sec-limpieza-cobertura .section-intro p | B4: text | D4: Vista consolidada por campus · Dotación agosto 2026 vs. cobertura 17/09 | E4: Texto de corte/introducción
A5: #sec-limpieza-presupuesto .section-intro p | B5: text | D5: Presupuesto 2026 y descuentos / penalidades registrados | E5: Texto de introducción
A6: #sec-operaciones-aula911 .section-intro p | B6: text | D6: Indicadores 2026 · corte 22/09 | E6: Fecha de corte Aula 911
A7: #sec-operaciones-rondas .section-intro p | B7: text | D7: Indicadores 2026 · corte 23/09 | E7: Fecha de corte Rondas
A8: #sec-proyectos-resumen .section-intro p | B8: text | D8: Portafolio consolidado y avance de obra / compras | E8: Texto de introducción
A9: #sec-mejoras-resumen .section-intro p | B9: text | D9: Consolidado por estado y programación mensual | E9: Texto de introducción
A10: #sec-listo-resumen .section-intro p | B10: text | D10: Estado de diseño, obra y operación por campus | E10: Texto de introducción

Sheet ENCABEZADOS
A1: hoja | B1: campo | C1: display_name | D1: orden | E1: visible | F1: formato
A2: LIMPIEZA_COBERTURA | B2: col_1 | C2: Zona | D2: 1 | E2: Sí
A3: LIMPIEZA_COBERTURA | B3: col_2 | C3: Campus | D3: 2 | E3: Sí
A4: LIMPIEZA_COBERTURA | B4: col_3 | C4: Turno Mañana | D4: 3 | E4: Sí
A5: LIMPIEZA_COBERTURA | B5: col_4 | C5: Turno Tarde | D5: 4 | E5: Sí
A6: LIMPIEZA_COBERTURA | B6: col_5 | C6: Turno Noche | D6: 5 | E6: Sí
A7: LIMPIEZA_COBERTURA | B7: col_6 | C7: Cobertura Mañana | D7: 6 | E7: Sí
A8: LIMPIEZA_COBERTURA | B8: col_7 | C8: Cobertura Tarde | D8: 7 | E8: Sí
A9: LIMPIEZA_COBERTURA | B9: col_8 | C9: Cobertura Noche | D9: 8 | E9: Sí
A10: LIMPIEZA_COBERTURA | B10: col_9 | C10: Pendiente Mañana | D10: 9 | E10: Sí
A11: LIMPIEZA_COBERTURA | B11: col_10 | C11: Pendiente Tarde | D11: 10 | E11: Sí
A12: LIMPIEZA_COBERTURA | B12: col_11 | C12: Pendiente Noche | D12: 11 | E12: Sí
A13: LIMPIEZA_COBERTURA | B13: col_12 | C13: # | D13: 12 | E13: Sí
... A54: LISTO | B54: col_7 | C54: Nueva fecha | D54: 7 | E54: Sí
A55: MEJORAS_PROGRAMACION | B55: col_1 | C55: CAMPUS | D55: 1 | E55: Sí | F55: texto
A56: MEJORAS_PROGRAMACION | B56: col_2 | C56: Fecha inicio | D56: 2 | E56: No | F56: fecha
A57: MEJORAS_PROGRAMACION | B57: col_3 | C57: Fecha fin | D57: 3 | E57: No | F57: fecha
A58: MEJORAS_PROGRAMACION | B58: col_4 | C58: <1/03/2026 | D58: 4 | E58: Sí | F58: entero
A59: MEJORAS_PROGRAMACION | B59: col_5 | C59: Mar | D59: 5 | E59: Sí | F59: entero
A60: MEJORAS_PROGRAMACION | B60: col_6 | C60: Abr | D60: 6 | E60: Sí | F60: entero
A61: MEJORAS_PROGRAMACION | B61: col_7 | C61: May | D61: 7 | E61: Sí | F61: entero
A62: MEJORAS_PROGRAMACION | B62: col_8 | C62: Jun | D62: 8 | E62: Sí | F62: entero
A63: MEJORAS_PROGRAMACION | B63: col_9 | C63: Jul | D63: 9 | E63: Sí | F63: entero
A64: MEJORAS_PROGRAMACION | B64: col_10 | C64: Ago | D64: 10 | E64: Sí | F64: entero
A65: MEJORAS_PROGRAMACION | B65: col_11 | C65: Set | D65: 11 | E65: Sí | F65: entero
A66: MEJORAS_PROGRAMACION | B66: col_12 | C66: Oct | D66: 12 | E66: Sí | F66: entero
... A69: MEJORAS_PROGRAMACION | B69: col_15 | C69: Total general | D69: 15 | E69: Sí | F69: entero

Sheet CONFIG_DASHBOARD
A1: clave | B1: valor | C1: descripcion
A2: archivo_excel | B2: BD_dashboard_operaciones_github.xlsx | C2: Nombre del archivo que debe leer el HTML
A3: anio | B3: 2026 | C3: Año de trabajo
A4: iniciativas_fecha_corte | B4: 01/03/2026 | C4: Fecha usada para la columna <1/03/2026
A5: aula911_fecha_corte | B5: 22/09/2026 | C5: Fecha de corte mostrada en Aula 911
A6: rondas_fecha_corte | B6: 23/09/2026 | C6: Fecha de corte mostrada en Rondas
A7: limpieza_cobertura_fecha_corte | B7: 17/09/2026 | C7: Fecha de cobertura
A8: limpieza_presupuesto_corte | B8: 30/09/2026 | C8: Corte del presupuesto/penalidades

Sheet KPIs_HTML
A1: modulo | B1: indicador | C1: valor | D1: unidad | E1: descripcion
A2: Limpieza | B2: Cobertura total | C2: 0.95 | D2: porcentaje | E2: Cobertura total
A3: Limpieza | B3: Cobertura semanal total | C3: 0.95 | D3: porcentaje | E3: Alias compatible con HTML
A4: Limpieza | B4: Dotación programada (turnos) | C4: 616 | D4: entero | E4: Turnos programados
A5: Limpieza | B5: Turnos cubiertos | C5: 584 | D5: entero | E5: Turnos cubiertos
A6: Limpieza | B6: Turnos pendientes | C6: 32 | D6: entero | E6: Turnos pendientes
A7: Limpieza | B7: Presupuesto 2026 | C7: 18000000 | D7: moneda | E7: Presupuesto
A8: Limpieza | B8: Presupuesto ejecutado | C8: 11200000 | D8: moneda | E8: Ejecutado
A9: Limpieza | B9: Nivel de ejecución | C9: 0.622 | D9: porcentaje | E9: Ejecutado / presupuesto
A10: Limpieza | B10: Descuentos + penalidades | C10: 222439 | D10: moneda | E10: Total
A11: Aula 911 | B11: # incidencias | C11: 23261 | D11: entero | E11: Incidencias
A12: Aula 911 | B12: Tiempo acepta solicitud | C12: 4.7 | D12: minutos | E12: Minutos
A13: Aula 911 | B13: Tiempo atiende solicitud | C13: 4.7 | D13: minutos | E13: Minutos
... A27: Listo | B27: Por implementar | C27: 7 | D27: entero | E27: Por implementar

Sheet LIMPIEZA_COBERTURA
A1: zona | B1: campus | C1: dot_m | D1: dot_t | E1: dot_n | F1: cob_m | G1: cob_t | H1: cob_n | I1: pend_m | J1: pend_t | K1: pend_n | L1: pend_total | M1: cobertura_pct
A2: LIMA | B2: SJL I | C2: 9 | D2: 8 | E2: 0 | F2: 9 | G2: 8 | H2: 0 | I2: 0 | J2: 0 | K2: 0 | L2: 0 | M2: 100
A3: LIMA | B3: ALMACEN CENTRAL | C3: 1 | D3: 0 | E3: 0 | F3: 1 | G3: 0 | H3: 0 | I3: 0 | J3: 0 | K3: 0 | L3: 0 | M3: 100
A4: LIMA | B4: JARRITA | C4: 3 | D4: 2 | E4: 0 | F4: 3 | G4: 2 | H4: 0 | I4: 0 | J4: 0 | K4: 0 | L4: 0 | M4: 100
A5: LIMA | B5: TORRE NUEVA | C5: 15 | D5: 15 | E5: 8 | F5: 15 | G5: 15 | H5: 8 | I5: 0 | J5: 0 | K5: 0 | L5: 0 | M5: 100
A6: LIMA | B6: LIMA NORTE | C6: 19 | D6: 19 | E6: 12 | F6: 19 | G6: 19 | H6: 12 | I6: 0 | J6: 0 | K6: 0 | L6: 0 | M6: 100
A7: PROVINCIA | B7: AREQUIPA POSTGRADO | C7: 1 | D7: 2 | E7: 0 | F7: 1 | G7: 2 | H7: 0 | I7: 0 | J7: 0 | K7: 0 | L7: 0 | M7: 100
A8: PROVINCIA | B8: CHIMBOTE | C8: 16 | D8: 10 | E8: 0 | F8: 16 | G8: 10 | H8: 0 | I8: 0 | J8: 0 | K8: 0 | L8: 0 | M8: 100
A9: PROVINCIA | B9: PIURA | C9: 15 | D9: 15 | E9: 8 | F9: 15 | G9: 15 | H9: 8 | I9: 0 | J9: 0 | K9: 0 | L9: 0 | M9: 100
A10: PROVINCIA | B10: TRUJILLO | C10: 8 | D10: 7 | E10: 0 | F10: 8 | G10: 7 | H10: 0 | I10: 0 | J10: 0 | K10: 0 | L10: 0 | M10: 100
A11: PROVINCIA | B11: HUANCAYO | C11: 13 | D11: 8 | E11: 0 | F11: 13 | G11: 8 | H11: 0 | I11: 0 | J11: 0 | K11: 0 | L11: 0 | M11: 100
A12: PROVINCIA | B12: HUANUCO | C12: 1 | D12: 0 | E12: 0 | F12: 1 | G12: 0 | H12: 0 | I12: 0 | J12: 0 | K12: 0 | L12: 0 | M12: 100
A13: PROVINCIA | B13: IQUITOS | C13: 9 | D13: 9 | E13: 0 | F13: 9 | G13: 9 | H13: 0 | I13: 0 | J13: 0 | K13: 0 | L13: 0 | M13: 100
... A29: LIMA | B29: JOSE DIAZ | C29: 4 | D29: 4 | E29: 0 | F29: 3 | G29: 3 | H29: 0 | I29: 1 | J29: 1 | K29: 0 | L29: 2 | M29: 75

Sheet LIMPIEZA_PRESUPUESTO
A1: concepto | B1: periodo | C1: monto
A2: Descuentos faltas/tardanzas | B2: 2026-05 | C2: 45862
A3: Descuentos faltas/tardanzas | B3: 2026-06 | C3: 37330
A4: Descuentos faltas/tardanzas | B4: 2026-07 | C4: 33645
A5: Descuentos faltas/tardanzas | B5: 2026-08 | C5: 33266
A6: Descuentos faltas/tardanzas | B6: 2026-09 | C6: 57771
A7: Penalidades | B7: 2026-05 | C7: 2507
A8: Penalidades | B8: 2026-06 | C8: 3902
A9: Penalidades | B9: 2026-07 | C9: 493
A10: Penalidades | B10: 2026-08 | C10: 583
A11: Penalidades | B11: 2026-09 | C11: 7080

Sheet AULA911_CAMPUS
A1: campus | B1: tiempo_acepta_min | C1: tiempo_atiende_min | D1: tiempo_total_min | E1: valoracion | F1: es_subsede
A2: CAMPUS CHIMBOTE | B2: 1.86 | C2: 2.95 | D2: 4.9 | E2: 4.7 | F2: 0
A3: CAMPUS TRUJILLO | B3: 1.98 | C3: 3.4 | D3: 5.4 | E3: 5 | F3: 0
A4: CAMPUS PIURA | B4: 2.54 | C4: 4.1 | D4: 6.6 | E4: 4.8 | F4: 0
A5: CAMPUS AREQUIPA | B5: 2.17 | C5: 4.07 | D5: 6.9 | E5: 4.8 | F5: 0
A6: Tacna y Arica | B6: 1.94 | C6: 4.34 | D6: 6.3 | E6: 4.8 | F6: 1
A7: Parra | B7: 3.14 | C7: 3.64 | D7: 6.8 | E7: 4.8 | F7: 1
A8: Parra 2 | B8: 3.22 | C8: 4.53 | D8: 7.7 | E8: 4.6 | F8: 1
A9: CAMPUS IQUITOS | B9: 2.59 | C9: 4.38 | D9: 7 | E9: 4.8 | F9: 0
A10: CAMPUS HUANCAYO | B10: 2.8 | C10: 4.34 | D10: 7.1 | F10: 0
A11: CAMPUS ATE UTP | B11: 1.7 | C11: 5.81 | D11: 7.4 | E11: 4.8 | F11: 0
A12: CAMPUS CHICLAYO | B12: 4.16 | C12: 3.54 | D12: 7.7 | E12: 4.6 | F12: 0
A13: CAMPUS SAN JUAN DE LURIGANCHO | B13: 4.15 | C13: 3.48 | D13: 7.7 | E13: 4.4 | F13: 0
A14: CAMPUS ICA | B14: 5.53 | C14: 2.79 | D14: 8.2 | E14: 3.2 | F14: 0
A15: CAMPUS LIMA | B15: 4.13 | C15: 4.17 | D15: 8.3 | E15: 3.8 | F15: 0
A16: Torre Petit Thouars | B16: 1.94 | C16: 2.63 | D16: 4.6 | E16: 3.4 | F16: 1
A17: Edificio Pacífico | B17: 2.27 | C17: 3.76 | D17: 6 | E17: 4.4 | F17: 1
A18: Torre Arequipa | B18: 4.31 | C18: 4.06 | D18: 8.4 | F18: 1
A19: Sede Central | B19: 7.85 | C19: 6.7 | D19: 14.5 | E19: 3.4 | F19: 1
A20: CAMPUS PUCALLPA | B20: 7.01 | C20: 2.19 | D20: 9.3 | E20: 4.8 | F20: 0
A21: CAMPUS TACNA | B21: 3.67 | C21: 6.13 | D21: 9.8 | E21: 5 | F21: 0
A22: CAMPUS LIMA NORTE UTP | B22: 9.03 | C22: 7.46 | D22: 16.6 | E22: 4.2 | F22: 0
A23: CAMPUS LIMA SUR UTP | B23: 10.28 | C23: 7.28 | D23: 17.5 | E23: 4.4 | F23: 0

Sheet AULA911_TOP
A1: tipo_incidencia | B1: participacion
A2: Problema con la PC | B2: 29
A3: Problema con el proyector | B3: 28
A4: Problema con el audio | B4: 13
A5: Problema con el Zoom | B5: 13
A6: Ambiente cerrado | B6: 17

Sheet RONDAS
A1: sede | B1: dispositivos_asignados | C1: responsables | D1: programado | E1: ejecutado | F1: cumplimiento_pct | G1: es_subsede
A2: 05. UTP Lima Sur | B2: 20 | C2: 16 | D2: 2464 | E2: 2753 | F2: 95 | G2: 0
A3: 04. UTP Ate | B3: 22 | C3: 12 | D3: 4638 | E3: 6058 | F3: 94 | G3: 0
A4: 03. UTP SJL | B4: 24 | C4: 9 | D4: 5057 | E4: 6152 | F4: 92 | G4: 0
A5: 11. UTP Huancayo | B5: 16 | C5: 7 | D5: 5026 | E5: 4575 | F5: 89 | G5: 0
A6: 07. UTP Chiclayo | B6: 53 | C6: 16 | D6: 10504 | E6: 11064 | F6: 83 | G6: 0
A7: 01. UTP Lima Centro | B7: 90 | C7: 33 | D7: 14434 | E7: 15220 | F7: 82 | G7: 0
A8: 03. UTP Lima Centro Torre Petit Thouars | B8: 19 | C8: 7 | D8: 5418 | E8: 5287 | F8: 97 | G8: 1
A9: 01. UTP Lima Centro Sede Central | B9: 36 | C9: 9 | D9: 1930 | E9: 1884 | F9: 84 | G9: 1
A10: 04. UTP Lima Centro Torre Pacífico | B10: 13 | C10: 7 | D10: 3812 | E10: 3147 | F10: 82 | G10: 1
A11: 02. UTP Lima Centro Torre Arequipa | B11: 22 | C11: 12 | D11: 3274 | E11: 4902 | F11: 59 | G11: 1
A12: 06. UTP Arequipa | B12: 65 | C12: 23 | D12: 14327 | E12: 14839 | F12: 80 | G12: 0
A13: 02. UTP Arequipa Parra I | B13: 22 | C13: 9 | D13: 4469 | E13: 4938 | F13: 88 | G13: 1
... A23: 15. UTP Tacna | B23: 66 | C23: 6 | D23: 12426 | E23: 2643 | F23: 20 | G23: 0

Sheet PROYECTOS
A1: proyecto | B1: estado | C1: avance_obra_pct | D1: avance_compras_pct | E1: fecha_objetivo_texto | F1: con_observaciones | G1: nueva_fecha_texto
A2: Nuevo Edificio Campus Lima Norte (Salud) – Por definir ITSE | B2: En proceso | C2: 98 | D2: 100 | E2: AGO 26 | F2: - | G2: -
A3: Laboratorios Salud Campus Lima Norte – ETAPA I – Pendiente ITSE | B3: En proceso | C3: 100 | D3: 100 | E3: OCT 26 | F3: - | G3: -
A4: Laboratorios de Técnicas Dietéticas y Terapia (Iquitos –Pucallpa) | B4: En proceso | C4: 100 | D4: 90 | E4: SET 26 | F4: - | G4: -
A5: Nuevo Campus Huánuco - SUNEDU - 12/10 | B5: En proceso | C5: 99 | D5: 100 | E5: OCT 26 | F5: - | G5: -
A6: Nuevo Campus Huamanga – SUNEDU 29/10 | B6: En proceso | C6: 98 | D6: 100 | E6: OCT 26 | F6: - | G6: -
A7: Nuevo Campus Juliaca – ITSE - 18/11 | B7: En proceso | C7: 87 | D7: 92.5 | E7: NOV 26 | F7: - | G7: -
A8: Nuevos Laboratorios de Hotelería y Turismo – Lima Centro - ITSE 09/12 | B8: En proceso | C8: 51 | D8: 0 | E8: ENE 27 | F8: - | G8: -
A9: Nuevos Laboratorios de Odontología – Lima Centro - Jarrita | B9: En proceso | C9: 15 | D9: 0 | E9: MAR 27 | F9: - | G9: -
A10: Nuevo Campus Cusco | B10: Pendiente | C10: 0 | D10: 0 | E10: JUL 27 | F10: - | G10: -
A11: Ampliación Campus Huancayo | B11: Pendiente | C11: 0 | D11: 0 | E11: AGO 27 | F11: - | G11: -
A12: Ampliación Campus Piura | B12: Pendiente | C12: 0 | D12: 0 | E12: AGO 27 | F12: - | G12: -
A13: Remodelación de Saco Oliveros | B13: En proceso | C13: 0 | D13: 0 | E13: DIC 15 | F13: - | G13: -
... A20: Medicina Piura | B20: Pendiente | C20: 0 | D20: 0 | E20: MAR 27 | F20: - | G20: -

Sheet PROYECTO_DETALLE
A1: campus | B1: descripcion | C1: avance_obra_pct | D1: avance_compras_pct | E1: avance_implementacion_pct | F1: fecha_objetivo_texto | G1: url_seguimiento
A2: Campus Huánuco | B2: 1 semisótano · 5 pisos · 1 azotea | C2: 99 | D2: 100 | E2: 95 | F2: OCT 26 | G2: https://seguimiento-proyectos-ops-utp.proyectos-ops-utp.workers.dev/?p=implementacion-nueva-sede-utp-huanuco-etapa-1&tab=p1
A3: Campus Huamanga | B3: 1 sótano · 5 pisos · 1 azotea | C3: 98 | D3: 100 | E3: 91 | F3: OCT 26 | G3: https://seguimiento-proyectos-ops-utp.proyectos-ops-utp.workers.dev/?p=implementacion-nueva-sede-utp-huamanga-etapa-1&tab=p1
A4: Campus Juliaca | B4: 1 sótano · 5 pisos · 1 azotea | C4: 87 | D4: 92.5 | E4: 35.5 | F4: NOV 26 | G4: https://seguimiento-proyectos-ops-utp.proyectos-ops-utp.workers.dev/?p=implementacion-nueva-sede-utp-juliaca-etapa-1&tab=p1
A5: Campus Lima Norte | B5: 4 sótanos · 1 semisótano · 7 pisos · 1 azotea | C5: 98 | D5: 95 | E5: 96.5 | F5: SET 26 | G5: https://seguimiento-proyectos-ops-utp.proyectos-ops-utp.workers.dev/?p=implementacion-nueva-torre-utp-lima-norte&tab=p1
A6: Proyecto Saco Olivero | B6: 1 semisótano · 9 pisos · 1 azotea | C6: 0 | D6: 0 | E6: 0 | F6: DIC 15 | G6: https://seguimiento-proyectos-ops-utp.proyectos-ops-utp.workers.dev/?p=implementacion-nueva-torre-utp-lima-norte&tab=p1

Sheet IMPLEMENTACIONES
A1: titulo | B1: avance_pct | C1: url
A2: Trujillo | ÁREAS DE ESPARCIMIENTO | B2: 64 | C2: https://lovely-horn-db6.notion.site/3d755146449f80c0a3cce29f4f317a51?v=3d755146449f802ba9a4000c451a72db
A3: Trujillo | ZONA DE FOTOCOPIADO | B3: 75 | C3: https://lovely-horn-db6.notion.site/3d755146449f80c0a3cce29f4f317a51?v=3d755146449f802ba9a4000c451a72db
A4: Trujillo | CAFETERÍA CONCESIONARIO | B4: 82 | C4: https://lovely-horn-db6.notion.site/3d755146449f80c0a3cce29f4f317a51?v=3d755146449f802ba9a4000c451a72db
A5: Trujillo | CAFETERÍA CAMPUS | B5: 83 | C5: https://lovely-horn-db6.notion.site/3d755146449f80c0a3cce29f4f317a51?v=3d755146449f802ba9a4000c451a72db
A6: SJL | ÁREAS DE ESPARCIMIENTO | B6: 33 | C6: https://lovely-horn-db6.notion.site/3d755146449f80c0a3cce29f4f317a51?v=3d755146449f802ba9a4000c451a72db
A7: SJL | ZONA DE FOTOCOPIADO | B7: 75 | C7: https://lovely-horn-db6.notion.site/3d755146449f80c0a3cce29f4f317a51?v=3d755146449f802ba9a4000c451a72db
A8: SJL | CAFETERÍA CONCESIONARIO | B8: 91 | C8: https://lovely-horn-db6.notion.site/3d755146449f80c0a3cce29f4f317a51?v=3d755146449f802ba9a4000c451a72db
A9: Piura | ÁREAS DE ESPARCIMIENTO | B9: 42 | C9: https://lovely-horn-db6.notion.site/3d755146449f80c0a3cce29f4f317a51?v=3d755146449f802ba9a4000c451a72db
A10: Piura | ZONA DE FOTOCOPIADO | B10: 100 | C10: https://lovely-horn-db6.notion.site/3d755146449f80c0a3cce29f4f317a51?v=3d755146449f802ba9a4000c451a72db
A11: Piura | CAFETERÍA CONCESIONARIO | B11: 64 | C11: https://lovely-horn-db6.notion.site/3d755146449f80c0a3cce29f4f317a51?v=3d755146449f802ba9a4000c451a72db
A12: Lima Sur | ÁREAS DE ESPARCIMIENTO | B12: 100 | C12: https://lovely-horn-db6.notion.site/3d755146449f80c0a3cce29f4f317a51?v=3d755146449f802ba9a4000c451a72db
... A55: Arequipa Parra 2 | CAFETERÍA CONCESIONARIO | B55: 82 | C55: https://lovely-horn-db6.notion.site/3d755146449f80c0a3cce29f4f317a51?v=3d755146449f802ba9a4000c451a72db

Sheet LISTO
A1: campus | B1: diseno_pct | C1: obra_pct | D1: operacion | E1: fecha_objetivo_texto | F1: con_observacion | G1: nueva_fecha_texto
A2: LC – Torre Tecnológica Arequipa (I) | B2: 100 | C2: 100 | D2: Sí | E2: Mar-26 | F2: No | G2: -
A3: LC – Sede Central (I) | B3: 100 | C3: 100 | D3: Sí | E3: Mar-26 | F3: Sí | G3: 6/04/2026
A4: LC – Torre II (I) | B4: 100 | C4: 100 | D4: Sí | E4: Mar-26 | F4: No | G4: -
A5: LS – Piso 1 (I) | B5: 100 | C5: 100 | D5: Sí | E5: Mar-26 | F5: No | G5: -
A6: LS – Piso 10 (I) | B6: 100 | C6: 100 | D6: Sí | E6: Mar-26 | F6: No | G6: -
A7: Ica (I) | B7: 100 | C7: 100 | D7: Sí | E7: Mar-26 | F7: No | G7: -
A8: Arequipa – Tacna y Arica (I) | B8: 100 | C8: 100 | D8: Sí | E8: Mar-26 | F8: No | G8: -
A9: LC – Pacífico (II) | B9: 100 | C9: 100 | D9: Sí | E9: Mar-26 | F9: Sí | G9: 13/04/2026
A10: SJL (II) | B10: 100 | C10: 100 | D10: Sí | E10: Mar-26 | F10: Sí | G10: 30/03/2026
A11: Arequipa – Parra 2 (II) | B11: 100 | C11: 100 | D11: Sí | E11: Mar-26 | F11: Sí | G11: 30/03/2026
A12: Trujillo (II) | B12: 100 | C12: 100 | D12: Sí | E12: Jun-26 | F12: No | G12: -
A13: Lima Norte (II) – Pendiente | B13: 100 | C13: 0 | D13: - | E13: - | F13: - | G13: -
A14: Chiclayo (II) | B14: 100 | C14: 0 | D14: - | E14: Oct-26 | F14: - | G14: -
A15: ATE (II) | B15: 100 | C15: 40 | D15: - | E15: Oct-26
A16: Pucallpa (III) | B16: 100 | C16: 0 | D16: - | E16: Nov-26 | F16: - | G16: -
A17: Iquitos (III) | B17: 90 | C17: 0 | D17: - | E17: Nov-26 | F17: - | G17: -
A18: Chimbote (III) | B18: 100 | C18: 0 | D18: - | E18: Nov-26 | F18: - | G18: -
A19: Resto de campus (IV) | B19: 0 | C19: 0 | D19: - | E19: - | F19: - | G19: -

Sheet BD_INICIATIVAS
B1: 5518026 | C1: PPTO OPS | D1: =+SUM(U7:U107) -> 5454483.2 | F1: =B1-D1 -> 63542.8
B2: 3192205 | C2: PPTO SSGG | D2: =+SUM(U108:U300) -> 3372510 | F2: =B2-D2 -> -180305.03 | R2: 8710231 | T2: 106806.94
B3: 8710231 | C3: TOTAL PPTO | D3: =+D1+D2 -> 8826993.2 | F3: =B3-D3 -> -116762.23
C4: TOTAL EJECUTADO | D4: =+SUM(V7:V300) -> 3312644.6 | R4: =R2-D3 -> -116762.23 | T4: =R2+T2 -> 8817037.9
A6: # | B6: ID | C6: ORIGEN2 | D6: RESPONSABLE DEL PROYECTO | E6: RESPONSABLE DEL PROYECTO2 | F6: CORREO | G6: TELÉFONO | H6: Columna1 | I6: BREVE DESCRIPCIÓN DEL PROYECTO | J6: LINK VIDEO / FOTOS | K6: ESTADO INICAL DE APROBACIÓN | L6: PUNTAJE PRIORIDAD | M6: IMPACTO SERVICIO AL ALUMNO | N6: IMPACTO IMAGEN / REPUTACIÓN | O6: IMPACTO EN OPERACIÓN | P6: COMENTARIOS DE INFRAESTRUCTURA | Q6: TIENE PRESUPUESTO | R6: CAMPUS | S6: UE | T6: UBICACIÓN PROYECTO (UE) | U6: MONTO INVERSIÓN DEL PROYECTO (INC IGV) | V6: MONTO EJECUTADO DEL PROYECTO (INC IGV) | W6: PRIORIDAD | X6: FECHA INICIO PLANIFICADA | Y6: FECHA FIN PLANIFICADA | Z6: FECHA INICIO REAL | AA6: FECHA FIN REAL | AB6: ESTADO PROYECTO OPERATIVO | AC6: ESTADO PROYECTO FINANCIERO | AD6: EJECUTOR | AE6: SC | AF6: FECHA INGRESO SC | AG6: OC | AH6: FECHA GENERACIÓN OC | AI6: CÓDIGO | AJ6: DESCRIPCIÓN PROYECTO | AK6: FECHA ATENCIÓN | AL6: ATENDIDO POR | AM6: Comentario | AN6: EFICIENCIA | AO6: Comentarios Eloy | AP6: Caso
A7: 1 | B7: OPS_001 | C7: OPS | D7: Nestor Silva | H7: ACONDICIONAR AMBIENTE AL COSTADO DE TOPICO EN TORREB PARA QUE SEA KITCHENET DOCENTE | I7: TORRE B NO TIENE ESPACIOS PARA DOCENTES (CAD KITCHENET), UTILIZAR EL ESPACIO DE LA OFICINA CONTIGUA AL TÓPICOQUE SE ENCUENTRA VACÍA COMO KITCHENNETTE PARA DOCENTES | J7: https://www,dropbox,com/scl/fo/t8a94dgffyjikmjdnamuh/ADI5WDjY4ELz_kWRkOXgTm8?rlkey=dtm5fyuuwarbzrhs4wqefssqt&dl=0 | K7: OK | L7: =SUM(M7:O7) -> 9 | M7: 1 | N7: 5 | O7: 3 | P7: OK para evaluar | Q7: SI | R7: UTP SJL | S7: 10220110 | T7: UTP AV,SOL SUB LT 13B MZG SJL - LIMA | U7: 25000 | V7: 25000 | W7: B | X7: 46235 | Y7: 46264 | AB7: EJECUTADO | AD7: Infraestructura | AI7: PROY1430 | AM7: Consultar con Infraestructura
A8: 2 | B8: OPS_002 | C8: OPS | D8: VICENTE CAYETANO RODRIGUEZ PASTOR | F8: vrodriguep@utp,edu,pe | G8: 955 141 444 | H8: Ampliación de la oficina de TI | I8: Necesidad de ampliar la oficina de Sistemas (TI) por la cantidad de colaboradores que allí laboran, Además el ambiente requiere contar con un área adecuada para el almacenamiento de equipos tecnológicos y la implementación del sistema biométrico lo que hace indispensable una ampliación que permita optimizar las condiciones de trabajo y seguridad, | J8: Proyectos CAPEX_PIURA - Dropbox | K8: OK | L8: =SUM(M8:O8) -> 9 | M8: 1 | N8: 3 | O8: 5 | Q8: SI | R8: UTP Piura | S8: 70170101 | T8: UTP AV,PANAMERICANA 234 -PIURA | U8: 20000 | V8: 9700 | W8: B | X8: 46082 | Y8: 46111 | Z8: 46082 | AA8: 46111 | AB8: EJECUTADO | AC8: EJECUTADO | AD8: Mantenimiento | AE8: SC-0000116696-2026 | AF8: 46063 | AG8: OC-0000122809-2026 | AH8: 46086 | AI8: MEJ00183 | AJ8: UTP_Piura_Ampliacion_Oficina _TI | AK8: 46055 | AL8: ESEVERINO
A9: 3 | B9: OPS_003 | C9: OPS | D9: Soledad Palacios | H9: Anaqueles para depósito de mantenimiento - Sótano 1 | I9: Materiales y herramientas en desorden impidiendo realizar un adecuado inventario | J9: https://www,dropbox,com/scl/fo/ygr8hf8nc7sv9xb4l0xwd/ALWiM47178yHX-TQzmGJhc0?rlkey=yl7begjvbrhyckomvjk2kiwdg&st=aslk3c2p&dl=0 | K9: OK | L9: =SUM(M9:O9) -> 10 | M9: 4 | N9: 2 | O9: 4 | Q9: SI | R9: UTP Trujillo | S9: 70180103 | T9: UTP NICOLAS PIEROLA - TRUJILLO | U9: 35000 | W9: A | X9: 46174 | Y9: 46295 | AB9: EN PROCESO | AD9: Campus | AE9: SC-0000115856-2026 | AI9: AM001207 | AJ9: UTP_Trujillo_Anaqueles_depósito_mantenimiento_Sótano 1 | AK9: 46055 | AL9: ESEVERINO | AM9: OC en cotización
A10: 4 | B10: OPS_004 | C10: OPS | D10: Marco Bonifaz | H10: Ascensor de escaleras para personas con discapacidad del piso 15 a la terraza en torre A y torre B, | I10: Los ascensores de ambas torres van hasta el piso 15 las personas con discapacidad no pueden acceder a la terraza del piso 16 en torre A tenemos espacios libres y próximamente a Listo y en la terraza de la torre B tenemos también espacios libres y zona de vida universitaria, | J10: EJEMPLO DE ASCENSOR DE ESCALERA PARA DISCAPACITADOS,jpg | K10: OK | L10: =SUM(M10:O10) -> 13 | M10: 3 | N10: 5 | O10: 5 | P10: Revisar di instalación de equipo perjudica evacuación del piso | Q10: SI | R10: UTP Lima Norte | S10: 10220111 | T10: UTP AV,INFANTAS MZ 2E LOTE 28, URB, STA LUISA - LOS OLIVOS | U10: 70000 | W10: A | X10: 46235 | Y10: 46356 | AB10: PENDIENTE | AD10: Infraestructura
A11: 5 | B11: OPS_005 | C11: OPS | D11: Eloy Pocohuanca | F11: epocohuanc@utp,edu,pe | G11: 937 029 622 | H11: Cambio de counter de biblioteca cambio de mesas de sala grupal cambio de Puff de SAE Implementación de sillas para VU | I11: Cambio de counter de biblioteca de mesas grupales de biblioteca de puff de SAE por deterioro implementación de sillas para la sala de vida universitaria y asi se le pueda dar usi incluso para las diversas actividades universitarias (taller etc) | Q11: SI | R11: UTP Chimbote | S11: 70150101 | T11: UTP PASERO DEL MAR MZ C9- LT2 - CHIMBOTE | U11: 15000 | V11: 11085 | W11: B | X11: 46082 | Y11: 46082 | Z11: 46082 | AA11: 46111 | AB11: EJECUTADO | AC11: EJECUTADO | AD11: Proyectos Ops | AE11: SC-0000118185-2026 / SC-0000120820-2026 | AF11: 46098 | AG11: OC-0000121793-2026 / OC-0000124082-2026 | AH11: 46098 | AI11: AM001195 | AJ11: UTP_Chimbote_Cambio_counter biblioteca_Puff de SAE_mesas grupales_implementacion sillas_VU | AK11: 46055 | AL11: ESEVERINO | AM11: generación de SC y OC: 24/02 / 17/03
A12: 6 | B12: OPS_006 | C12: OPS | D12: Carlos Sanchez Pariona | F12: csanchezp@utp,edu,pe | G12: 951 317 089 | H12: Cambio de grifería y trampas en 50 baños de Torre Petit Thoaurs | I12: Para la mejora en la experiencia alumno y su impacto en NPS se requiere cambio de grifería trampas desagüe en 50 baños | J12: https://www,dropbox,com/scl/fi/2htg1gbdek9wr6e2g0y57/Iniciativas-mejora-2025,pptx?rlkey=ucwlfkeatbngte3u1q2nij5lp&st=ukeg7lj8&dl=0 | K12: OK | L12: =SUM(M12:O12) -> 8 | M12: 2 | N12: 5 | O12: 1 | Q12: SI | R12: UTP Lima Centro | S12: 10110204 | T12: UTP PETIT THOU383-385-TORRE II - LIMA | U12: 26000 | V12: 16374.52 | W12: C | X12: 46174 | Y12: 46295 | Z12: 46132 | AB12: EN PROCESO | AD12: Mantenimiento | AE12: SC-0000116432-2026 / SC-0000122792-2026 | AF12: 46119 | AG12: OC-0000125881-2026 / OC-0000128442-2026 | AH12: 07/04 / 30/04 | AI12: MEJ00184 | AJ12: UTP_PTT383-385_Cambio_griferia_trampas _50 baños_Torre II | AK12: 46055 | AL12: ESEVERINO | AM12: SE ENVIÓ NR OC-0000125881-2026
A13: 7 | B13: OPS_007 | C13: OPS | D13: Carlos Sanchez Pariona | F13: csanchezp@utp,edu,pe | G13: 951 317 089 | H13: Cambio de línea de desague en Torre Petit Thoaurs | I13: Cambio de línea matriz de desagüe ambos montantes por constantes atoros, Antigüedad mayor a 20 años | J13: https://www,dropbox,com/scl/fi/2htg1gbdek9wr6e2g0y57/Iniciativas-mejora-2025,pptx?rlkey=ucwlfkeatbngte3u1q2nij5lp&st=ukeg7lj8&dl=0 | K13: OK | L13: =SUM(M13:O13) -> 11 | M13: 1 | N13: 5 | O13: 5 | Q13: SI | R13: UTP Lima Centro | S13: 10110204 | T13: UTP PETIT THOU383-385-TORRE II - LIMA | U13: 87457.3 | V13: 84268.51 | W13: A | X13: 46174 | Y13: 46295 | Z13: 46193 | AB13: EN PROCESO | AD13: Mantenimiento | AE13: SC-0000116816-2026 | AF13: 46063 | AG13: OC-0000133232-2026 | AH13: 46175 | AI13: MEJ00185 | AJ13: UTP_PTT383-385_Cambio_línea desague_Torre II | AK13: 46055 | AL13: ESEVERINO | AO13: Presupuesto se amplia a 87 K
A14: 8 | B14: OPS_008 | C14: OPS | D14: Elmer Raul ILLANES PAUCAR | F14: eillanes@utp,edu,pe | G14: 994 690 404 | H14: Cambio de piso de biblioteca por porcelanato | I14: El piso actual presenta desgaste significativo del material debido al propio uso estando en muy mal estado por algunas zonasadiconal dicho material no ha sido reemplazado desde el 2018, | J14: PISO BIBLIOTECA | K14: OK | L14: =SUM(M14:O14) -> 9 | M14: 3 | N14: 5 | O14: 1 | Q14: SI | R14: UTP Lima Este | S14: 10220108 | T14: UTP N,AYLLON KM11,60 LOTE 96ATE -LIMA | U14: 71200 | V14: 71200 | W14: B | X14: 46082 | Y14: 46082 | Z14: 46082 | AA14: 46111 | AB14: EJECUTADO | AC14: EJECUTADO | AD14: Mantenimiento | AE14: SC-0000116464-2026 | AF14: 46060 | AG14: OC-0000121837-2026 | AH14: 46077 | AI14: MEJ00186 | AJ14: UTP_Ate KM11,60_Cambio_piso biblioteca_porcelanato | AK14: 46055 | AL14: ESEVERINO | AO14: Revisar con Finanzas
A15: 9 | B15: OPS_009 | C15: OPS | D15: Elmer Raul ILLANES PAUCAR | F15: eillanes@utp,edu,pe | G15: 994 690 404 | H15: Cambio de piso de biblioteca por porcelanato | I15: El piso actual presenta desgaste significativo del material debido al propio uso estando en muy mal estado por algunas zonasadiconal dicho material no ha sido reemplazado desde el 2018, | K15: OK | L15: =SUM(M15:O15) -> 9 | M15: 3 | N15: 5 | O15: 1 | Q15: SI | R15: UTP Lima Norte | S15: 10220111 | T15: UTP AV,INFANTAS MZ 2E LOTE 28, URB, STA LUISA - LOS OLIVOS | U15: 130000 | V15: 144753.79 | W15: B | X15: 46082 | Y15: 46082 | Z15: 46082 | AA15: 46111 | AB15: EJECUTADO | AC15: EJECUTADO | AD15: Mantenimiento | AE15: SC-0000116465-2026 | AF15: 46060 | AG15: OC-0000123203-2026 | AH15: 46091 | AI15: MEJ00187 | AJ15: UTP_LN Mz Lote 28_Cambio_piso biblioteca_porcelanato | AK15: 46055 | AL15: ESEVERINO
A16: 10 | B16: OPS_010 | C16: OPS | D16: Gustavo Mallaupoma | H16: Cambio de piso laminado por porcelanato en el laboratorio de terapias física de Sede Central | I16: El piso instalado para el laboratorio de terapia física no es el adecuado al no ser óptimo para alto tránsito así mismo no está dentro del estándar de pisos instalados en otros campus, En la actualidad el piso se encuentra totalmente desgastado y genera una muy mala imagen para los estudiantes, | J16: https://drive,google,com/drive/folders/1P0EWUzgUa6s_t8Xe0GcagbXeceSvYmfn | K16: OK | L16: =SUM(M16:O16) -> 10 | M16: 4 | N16: 5 | O16: 1 | Q16: SI | R16: UTP Lima Centro | S16: 10110201 | T16: UTP PETITTHOURS 116 - LIMA | U16: 30000 | V16: 14355.5 | W16: A | X16: 46082 | Y16: 46082 | Z16: 46082 | AA16: 46111 | AB16: EJECUTADO | AC16: EJECUTADO | AD16: Mantenimiento | AE16: SC-0000117935-2026 | AF16: 46073 | AG16: OC-0000122833-2026 | AH16: 46086 | AI16: MEJ00188 | AJ16: UTP_PTT116_Cambio_piso laminado_porcelanato_laboratorio_terapias fisicas | AK16: 46055 | AL16: ESEVERINO | AM16: Conversar con Fredy
A17: 11 | B17: OPS_011 | C17: OPS | D17: Carlos Sanchez Pariona | F17: csanchezp@utp,edu,pe | G17: 951 317 089 | H17: Cambio de porcelanatos en ambientes críticos con levantamientos/roturas diferente color en Torre Petit Thoaurs, | I17: El porcelanato de 44 ambientes académicos se encuentra levantados y/o rajados, Hay 21 ambientes críticos que se localizan entre el piso 7 y 14,Se adjunta excel en link con el detalle | J17: Porcelanatos TORRE2 | K17: OK | L17: =SUM(M17:O17) -> 9 | M17: 3 | N17: 5 | O17: 1 | Q17: SI | R17: UTP Lima Centro | S17: 10110204 | T17: UTP PETIT THOU383-385-TORRE II - LIMA | U17: 258000 | V17: 156958.9 | W17: B | X17: 46174 | Y17: 46295 | Z17: 46132 | AB17: EN PROCESO | AD17: Mantenimiento | AE17: SC-0000116467-2026 | AF17: 46060 | AG17: OC-0000124295-2026 | AH17: 46100 | AI17: MEJ00189 | AJ17: UTP_PTT383-385_Cambio_porcelanatos_ambientes criticos | AK17: 46055 | AL17: ESEVERINO
A18: 12 | B18: OPS_012 | C18: OPS | D18: Carlos Sanchez Pariona | F18: csanchezp@utp,edu,pe | G18: 951 317 089 | H18: Cambio del techo del comedor | I18: Techo del comedor está en mal estado la limpieza no es suficiente las planchas de policarbonato están descoloridas, Estéticamente impacta en la imagen del Campus se ve mal | J18: TECHO COMEDOR ATE | K18: OK | L18: =SUM(M18:O18) -> 11 | M18: 5 | N18: 5 | O18: 1 | Q18: SI | R18: UTP Lima Este | S18: 10220108 | T18: UTP N,AYLLON KM11,60 LOTE 96ATE -LIMA | U18: 32000 | V18: 46990.9 | W18: A | X18: 46174 | Y18: 46295 | Z18: 46132 | AB18: EN PROCESO | AD18: Mantenimiento | AE18: SC-0000116469-2026 | AF18: 46060 | AG18: OC-0000124831-2026 | AH18: 46105 | AI18: MEJ00190 | AJ18: UTP_Ate KM11,60_Cambio_techo_comedor | AK18: 46055 | AL18: ESEVERINO
A19: 13 | B19: OPS_013 | C19: OPS | D19: VICENTE CAYETANO RODRIGUEZ PASTOR | F19: vrodriguep@utp,edu,pe | G19: 955 141 444 | H19: Cambio sistema de bombeo de presión constante torre A | I19: Sistema de bombeo de agua de torre A tiene mas de 7 años de antigüedad se tiene con frecuencia caidas de presión y deja sin agua a torre A los tableros de control no permite el funcionamiento de 02 bombas a la vez para aliviar la presión, Son dos bombas por Us 12k | J19: 6 | K19: OK | L19: =SUM(M19:O19) -> 9 | M19: 1 | N19: 3 | O19: 5 | Q19: SI | R19: UTP Lima Sur | S19: 10220106 | T19: UTP EL TRIUNFO S/N-VILLA SALVA - LIMA | U19: 128000 | V19: 125982.76 | W19: B | X19: 46082 | Y19: 46082 | Z19: 46082 | AA19: 46111 | AB19: EJECUTADO | AC19: EJECUTADO | AD19: Mantenimiento | AE19: SC-0000116814-2026 | AF19: 46063 | AG19: OC-0000123018-2026 | AH19: 46087 | AI19: MEJ00191 | AJ19: UTP_VES_Cambio_sistema_bombeo presion constante_torre A | AK19: 46055 | AL19: ESEVERINO
A20: 14 | B20: OPS_014 | C20: OPS | D20: Nestor Silva | H20: Construcción de Caseta de Vigilancia | I20: Actualmente no contamos con caseta y el ecritorio en "L" se encuentra expuesto y a riesgo de extravío de llaves y DNI | J20: https://www,dropbox,com/scl/fi/eba9a8xdt27v27lynl3yp/espacio-de-vigilantes-en-sede-sin-caseta,jpg?rlkey=h8ytg6opg0ibyf17t4laksicw&st=thdy8ie3&dl=0 | K20: OK | L20: =SUM(M20:O20) -> 11 | M20: 2 | N20: 4 | O20: 5 | P20: OK a evaluar presupuesto insuficiente | Q20: SI | R20: UTP Ica | S20: 70160101 | T20: UTP SUB EUB-5 SAN JOSE - ICA | U20: 18000 | W20: A | X20: 46235 | Y20: 46356 | AB20: PENDIENTE | AD20: Infraestructura
A21: 15 | B21: OPS_015 | C21: OPS | D21: CARLA CELI | H21: Depósito y estantería para SSUU (en esquina zona deportiva) | Q21: SI | R21: UTP Trujillo | S21: 70180103 | T21: UTP NICOLAS PIEROLA - TRUJILLO | U21: 45000 | W21: B | X21: 46235 | Y21: 46356 | AB21: PENDIENTE | AD21: Infraestructura
A22: 16 | B22: OPS_016 | C22: OPS | D22: Luis García | H22: Equipo de AA para cuarto de servidores torre A | I22: Climatización del cuarto de servidores de la torre A área crítica por contar con equipos de comunicación operativos 24/7 | J22: https://www,dropbox,com/scl/fi/wnlt33yfldc6wo0joscax/Data_CIX,png?rlkey=fmvsqv89rz8up9ygn2qdp9f6x&st=5qsbjec3&dl=0 | K22: OK | L22: =SUM(M22:O22) -> 9 | M22: 4 | N22: 1 | O22: 4 | Q22: SI | R22: UTP Chiclayo | S22: 70120201 | T22: UTP AV, PROGRESO CON AV, EVITAMIENTO S/N - CHICLAYO | U22: 6000 | V22: 6107.66 | W22: B | X22: 46174 | Y22: 46295 | AB22: EN PROCESO | AD22: Mantenimiento | AE22: SC-0000116471-2026 | AF22: 46060 | AG22: SC DEVUELTA | AI22: PROY1379 | AJ22: UTP_Chiclayo_Equipo AA_cuarto_servidores torre A | AK22: 46055 | AL22: ESEVERINO | AM22: Solicitud devuelta responsable no confirma obs de planos
A23: 17 | B23: OPS_017 | C23: OPS | D23: VICENTE CAYETANO RODRIGUEZ PASTOR | F23: vrodriguep@utp,edu,pe | G23: 955 141 444 | H23: Habilitar puntos de agua para sardinel | I23: En convenio con la municipalidad el área de sardinel fue cedida para mantenimiento actualmente al no tener punto de agua no se puede realizar, Se evidencia en el video la actual condición, | J23: Puntos de agua,mp4 | K23: OK | L23: =SUM(M23:O23) -> 8 | M23: 1 | N23: 4 | O23: 3 | Q23: SI | R23: UTP Chimbote | S23: 70150101 | T23: UTP PASERO DEL MAR MZ C9- LT2 - CHIMBOTE | U23: 15000 | V23: 6107.66 | W23: C | X23: 46082 | Y23: 46203 | Z23: 46082 | AA23: 46170 | AB23: EJECUTADO | AC23: EJECUTADO | AD23: Mantenimiento | AE23: SC-0000116786-2026 | AF23: 46063 | AG23: OC-0000122376-2026 | AH23: 46084 | AI23: PROY1380 | AJ23: UTP_Chimbote_Habilitar_puntos agua_sardinel | AK23: 46055 | AL23: ESEVERINO
A24: 18 | B24: OPS_018 | C24: OPS | D24: Katherine Polo | H24: Iluminación del nombre de la Universidad | J24: FOTOS NOMBRE LOGOS UTP | Q24: SI | R24: UTP Lima Sur | S24: 10220106 | T24: UTP EL TRIUNFO S/N-VILLA SALVA - LIMA | U24: - | W24: B | AB24: CANCELADO | AD24: Infraestructura
A25: 19 | B25: OPS_019 | C25: OPS | D25: Katherine Polo | H25: Iluminación del nombre de la Universidad | J25: FOTOS NOMBRE LOGOS UTP | Q25: SI | R25: UTP Lima Norte | S25: 10220111 | T25: UTP AV,INFANTAS MZ 2E LOTE 28, URB, STA LUISA - LOS OLIVOS | U25: 24250 | W25: B | X25: 46235 | Y25: 46356 | AB25: PENDIENTE | AD25: Infraestructura
A26: 20 | B26: OPS_020 | C26: OPS | D26: Katherine Polo | H26: Iluminación del nombre de la Universidad | J26: FOTOS NOMBRE LOGOS UTP | Q26: SI | R26: UTP Lima Centro | S26: 10110102 | T26: UTP AREQUIPA 660- 670 - LIMA | U26: 24250 | W26: B | X26: 46235 | Y26: 46356 | AB26: PENDIENTE | AD26: Infraestructura | AM26: Pendiente en consulta
A27: 21 | B27: OPS_021 | C27: OPS | D27: Katherine Polo | H27: Iluminación del nombre de la Universidad | I27: Las letras negras "Universidad Tecnológica del Perú" sin iluminación pasan desapercibidas en la noche, En SJL ATE si están iluminadas | J27: FOTOS NOMBRE LOGOS UTP | K27: OK | L27: =SUM(M27:O27) -> 9 | M27: 2 | N27: 5 | O27: 2 | P27: OK para evaluar poner iluminación con reflectores | Q27: SI | R27: UTP Lima Centro | S27: 10110204 | T27: UTP PETIT THOU383-385-TORRE II - LIMA | U27: 24250 | W27: B | X27: 46235 | Y27: 46356 | AB27: PENDIENTE | AD27: Infraestructura
A28: 22 | B28: OPS_022 | C28: OPS | D28: Gustavo Mallaupoma | H28: Impermeabilización de los pisos de todos los baños de la torre | I28: Existen filtraciones de agua hacia pisos inferiores en los SSHH del campus cuando se ejecuta la limpieza de los mismos por parte de Limtek, Esto genera daño a las baldosas lo cual implica estar cambiandolas constantemente, | J28: https://www,dropbox,com/scl/fi/ji89dac31y2yls6rsyl4m/Huancayo_Mejoras,pptx?rlkey=sdwbvs1liw2b8mgovq0bq8nn5&st=q1lvojps&dl=0 | K28: OK | L28: =SUM(M28:O28) -> 12 | M28: 3 | N28: 4 | O28: 5 | Q28: SI | R28: UTP Huancayo | S28: 70190101 | T28: UTP AV,CIRCUNVALACIÓN 449 - HUANCAYO | U28: 13000 | V28: 13919.28 | W28: A | X28: 46082 | Y28: 46111 | Z28: 46082 | AA28: 46111 | AB28: EJECUTADO | AC28: EJECUTADO | AD28: Mantenimiento | AE28: SC-0000118739-2026 | AF28: 46081 | AG28: OC-0000123888-2026 | AH28: 46097 | AI28: MEJ00192 | AJ28: UTP_Hcyo_Impermeabilizacion _pisos_baños_torre | AK28: 46055 | AL28: ESEVERINO
A29: 23 | B29: OPS_023 | C29: OPS | D29: Ricardo Jacobo | H29: Impermeabilización y revestimiento de azotea | I29: Para evitar las filtraciones es necesario contar con una impermeabilización de toda la azotea completa, No tiene impermeabilización y presenta filtraciones constantes , En el Bloque C han parchado por zonas puntuales cuando han habido filtraciones | J29: 3 | K29: OK | L29: =SUM(M29:O29) -> 9 | M29: 1 | N29: 5 | O29: 3 | P29: OK para evaluar | Q29: SI | R29: UTP Lima Sur | S29: 10220106 | T29: UTP EL TRIUNFO S/N-VILLA SALVA - LIMA | U29: 140000 | W29: B | X29: 46235 | Y29: 46356 | AB29: PENDIENTE | AD29: Infraestructura | AM29: Se modificó monto de 160K a 140K | AO29: Revisar cambiar de monto
A30: 24 | B30: OPS_024 | C30: OPS | D30: Eloy Pocohuanca/Carlos S, | F30: epocohuanc@utp,edu,pe | G30: 937 029 622 | H30: Implemenrar área libre para alumnos en el sum del piso 15 Torre 2, Local no tiene áreas libres para alumnos | I30: Propuesta de retirar la tabiquería y puerta del SUM del piso 15 para poder ganar espacio para aumentar dos mesas más adicionales al ambiente, Tamaño final 45,6 m2, El uso del ambiente es intensivo y es uno de los pocos ambientes con los que los alumnos cuentan para avanzar sus trabajos con laptop y en horario de refrigerio para poder almorzar, Adicionalmente incluye la renovación de 8 mesas y 32 sillas más compra de 2 mesas y 8 sillas, | J30: https://www,dropbox,com/scl/fo/045w1pv87upfjolydrkn3/APvbKb6m3Z9c9rvOZuyvhSI?rlkey=flxw6v94kr6egfxz6leroshzj&st=fps3xzwp&dl=0 | K30: OK | L30: =SUM(M30:O30) -> 11 | M30: 5 | N30: 5 | O30: 1 | Q30: SI | R30: UTP Lima Centro | S30: 10110204 | T30: UTP PETIT THOU383-385-TORRE II - LIMA | U30: 20000 | W30: A | X30: 46266 | Y30: 46326 | AB30: PENDIENTE | AD30: Proyectos Ops | AE30: SC-0000143394-2026 | AF30: 46274 | AI30: PROY1381 | AJ30: UTP_PTT_383-385_Implementar_area libre_alumnos_piso 15 Torre 2 | AK30: 46055 | AL30: ESEVERINO | AM30: Conversar con Jossi coordina Julio
A31: 25 | B31: OPS_025 | C31: OPS | D31: Marco Bonifaz | H31: Implementación de almacén en azotea | P31: OK a evaluar se debe tener en cuanta trámite de conformidad d eobra en curso | Q31: SI | R31: UTP Piura | S31: 70170101 | T31: UTP AV,PANAMERICANA 234 -PIURA | U31: 80000 | W31: B | X31: 46235 | Y31: 46356 | AB31: PENDIENTE | AD31: Infraestructura
A32: 26 | B32: OPS_026 | C32: OPS | D32: Marco Bonifaz | H32: Implementación de depósito adicional | I32: No contamos con espacio suficiente para el almacenamiento de diversos materiales activos y demás objetos los cuales son de uso continuo en sede lo que nos obliga a guardarlos en espacios no adecuados, Lo cual a la vista de la comunidad universitaria e instituciones reguladoras serian altamente e inclusi motivo de sanción, Se propone la utilización de dos espacios para vehículos del estacionamiento del semisótano para esta nueva implementación ya que actualmente contamos espacios en el patio los cuales pueden servir para suplir la necesidad generada de espacios para el estacionamiento, | Q32: SI | R32: UTP Huancayo | S32: 70190101 | T32: UTP AV,CIRCUNVALACIÓN 449 - HUANCAYO | U32: 15000 | W32: B | X32: 46235 | Y32: 46356 | AB32: PENDIENTE | AD32: Infraestructura
A33: 27 | B33: OPS_027 | C33: OPS | D33: Gustavo Mallaupoma | H33: Implementación de puntos eléctricos en el patio | I33: En sede no contamos con espacios amplios para el desarrollo de eventos muchos de ellos se han realizado en el patio como el taller de danzas aniversario de la sede feria de emprendimiento entre otras, Estas actividades demandan contar con puntos eléctricos para que los equipos funcionen y se realice las actividades convenientemente, | J33: Fotos para mejoras 1,pptx | K33: OK | L33: =SUM(M33:O33) -> 10 | M33: 4 | N33: 2 | O33: 4 | Q33: SI | R33: UTP Huancayo | S33: 70190101 | T33: UTP AV,CIRCUNVALACIÓN 449 - HUANCAYO | U33: 18000 | V33: 12991.8 | W33: A | X33: 46082 | Y33: 46082 | Z33: 46082 | AA33: 46111 | AB33: EJECUTADO | AC33: EJECUTADO | AD33: Mantenimiento | AE33: SC-0000118740-2026 | AF33: 46081 | AG33: OC-0000123883-2026 | AH33: 46097 | AI33: MEJ00193 | AJ33: UTP_Hcyo_Implementacion_puntos electricos_patio | AK33: 46055 | AL33: ESEVERINO
A34: 28 | B34: OPS_028 | C34: OPS | D34: Gustavo Mallaupoma | H34: Implementación de sumideros en el laboratorio de procesos industriales | I34: Implementar cuatro sumideros adicionales en el piso del laboratorio, Cuando se realiza la limpieza de equipos el agua se queda acumulada debajo de estas y la limpieza del ambiente demora, La limpiea toma mas tiempo del previsto para el asistente del laboratorio, Asi mismo; el riesgo accidentes por el piso que se vuelve resbaloso | J34: Fotos para mejoras 1,pptx | K34: OK | L34: =SUM(M34:O34) -> 10 | M34: 4 | N34: 2 | O34: 4 | Q34: SI | R34: UTP Huancayo | S34: 70190101 | T34: UTP AV,CIRCUNVALACIÓN 449 - HUANCAYO | U34: 10000 | V34: 8510.48 | W34: A | X34: 46082 | Y34: 46172 | Z34: 46082 | AA34: 46172 | AB34: EJECUTADO | AC34: EJECUTADO | AD34: Mantenimiento | AE34: SC-0000118741-2026 | AF34: 46081 | AG34: OC-0000123225-2026 | AH34: 46091 | AI34: MEJ00194 | AJ34: UTP_Hcyo_Implementacion_sumideros_laboratorio | AK34: 46055 | AL34: ESEVERINO
A35: 29 | B35: OPS_029 | C35: OPS | D35: Eloy / Raul | H35: Implementación de tomacorrientes para mesas de salas de estudio en biblioteca | I35: Suminstro e instalación de 48 puntos de energia | J35: Tacna y Arica – Mesas biblioteca,pdf | K35: OK | L35: =SUM(M35:O35) -> 11 | M35: 4 | N35: 3 | O35: 4 | Q35: SI | R35: UTP Arequipa | S35: 70110101 | T35: UTP TACNA-ARICA 158-160-162 - AREQUIPA | U35: 20000 | W35: A | X35: 46203 | Y35: 46325 | AB35: PENDIENTE | AD35: Proyectos Ops / Mantenimiento | AE35: SC-0000118273-2026 | AF35: 46077 | AG35: SC DEVUELTA | AI35: MEJ00195 | AJ35: UTP_Arq 158-160_Implementacion_tomacorrientes_mesas_biblioteca | AK35: 46055 | AL35: ESEVERINO | AM35: SC devuelta a la espera de nuevo alcance | AP35: ELOY
A36: 31 | B36: OPS_030 | C36: OPS | D36: Eloy / Raul | H36: Implementación de tomacorrientes para mesas de salas de estudio en biblioteca | I36: Renovación de mobiliario con integración de puntos eléctricos retráctiles en mesas de trabajo (sala lectura 01) y el sala lectura 2 se mantiene el mobiliario | J36: https://utpedupe,sharepoint,com/:f:/s/OperacionesCIX/EuVMG6DEAQZNp7fh5H-BPcIBEBuJg4Cyzmy5w2K40DH5-g?e=sAAUob | K36: OK | L36: =SUM(M36:O36) -> 11 | M36: 4 | N36: 3 | O36: 4 | Q36: SI | R36: UTP Chiclayo | S36: 70120201 | T36: UTP AV, PROGRESO CON AV, EVITAMIENTO S/N - CHICLAYO | U36: 21000 | V36: 21000 | W36: A | X36: 46174 | Y36: 46264 | AB36: EJECUTADO | AC36: PENDIENTE | AD36: Proyectos Ops / Mantenimiento | AE36: SC-0000137984-2026 | AF36: 46225 | AG36: OC-0000142670-2026 | AH36: 46100 | AI36: MEJ00196 | AJ36: UTP_Chiclayo_Implementacion_tomacorrientes_mesas_biblioteca | AK36: 46055 | AL36: ESEVERINO | AM36: Se canceló OC-0000124398-2026 por nuevo alcance/ OC-0000142670-2026 nr
A37: 32 | B37: OPS_031 | C37: OPS | D37: Eloy / Raul | H37: Implementación de tomacorrientes para mesas de salas de estudio en biblioteca | I37: Se adjunta cotización para energizar 10 mesas con toma eléctrica doble (20 puntos de energía) | J37: https://utpedupe-my,sharepoint,com/:i:/g/personal/etirado_utp_edu_pe/Eb8rAbMwJuBHi885UHeD0T0BSpgRhLu8HVJCDLvxjOF6IA?e=QkVs4N | K37: OK | L37: =SUM(M37:O37) -> 11 | M37: 4 | N37: 3 | O37: 4 | Q37: SI | R37: UTP Chimbote | S37: 70150101 | T37: UTP PASERO DEL MAR MZ C9- LT2 - CHIMBOTE | U37: 15800 | V37: 15444.22 | W37: A | X37: 46082 | Y37: 46203 | Z37: 46082 | AA37: 46143 | AB37: EJECUTADO | AC37: PENDIENTE | AD37: Proyectos Ops / Mantenimiento | AE37: SC-0000118552-2026 | AF37: 46079 | AG37: OC-0000124582-2026 | AH37: 46102 | AI37: MEJ00197 | AJ37: UTP_Chimbote_Implementacion_tomacorrientes_mesas_biblioteca | AK37: 46055 | AL37: ESEVERINO | AM37: Pendiente de NR
A38: 33 | B38: OPS_032 | C38: OPS | D38: Eloy / Raul | H38: Implementación de tomacorrientes para mesas de salas de estudio en biblioteca | I38: Se cuenta con una parte de las mesas con puntos de energía dento de biblioteca y se mapearon un total de 52 puntos de energía faltantes por lo cual se requiere la energización en 20 puntos para mesas en la sala de lectura y 32 puntos para mesas en la sala de estudio, El costo es referencial en base a la instalación previa de 9 puntos de energía en uno de los laboratorios del campus, | J38: INSTALACIÓN DE PUNTOS DE ENERGIA EN BIBLIOTECA | K38: OK | L38: =SUM(M38:O38) -> 11 | M38: 4 | N38: 3 | O38: 4 | Q38: SI | R38: UTP Huancayo | S38: 70190101 | T38: UTP AV,CIRCUNVALACIÓN 449 - HUANCAYO | U38: 18000 | V38: 16475.75 | W38: A | X38: 46082 | Y38: 46111 | Z38: 46082 | AA38: 46111 | AB38: EJECUTADO | AC38: EJECUTADO | AD38: Proyectos Ops / Mantenimiento | AE38: SC-0000117917-2026 | AF38: 46073 | AG38: OC-0000124862-2026 | AH38: 46105 | AI38: MEJ00198 | AJ38: UTP_Hcyo_Implementacion_tomacorrientes_mesas_biblioteca | AK38: 46055 | AL38: ESEVERINO
A39: 34 | B39: OPS_033 | C39: OPS | D39: Eloy / Raul | H39: Implementación de tomacorrientes para mesas de salas de estudio en biblioteca | I39: Se requiere instalar 42 puntos electricos para biblioteca, | J39: https://utpedupe-my,sharepoint,com/personal/hleon_utp_edu_pe/_layouts/15/onedrive,aspx?id=%2Fpersonal%2Fhleon%5Futp%5Fedu%5Fpe%2FDocuments%2FUTP%2FAREA%20OPERACIONES%20%2D%20COMPARTIDO%2FCAPEX%20ADICIONALES%202026%2FEnergizar%20mesas%20de%20Biblioteca&viewid=dc302f51%2D364c%2D45d8%2Db630%2D7c45cef7440a&ga=1 | K39: OK | L39: =SUM(M39:O39) -> 11 | M39: 4 | N39: 3 | O39: 4 | Q39: SI | R39: UTP Ica | S39: 70160101 | T39: UTP SUB EUB-5 SAN JOSE - ICA | U39: 24260 | V39: 14030.27 | W39: A | X39: 46082 | Y39: 46172 | Z39: 46082 | AA39: 46142 | AB39: EJECUTADO | AC39: EJECUTADO | AD39: Proyectos Ops / Mantenimiento | AE39: SC-0000117916-2026 | AF39: 46073 | AG39: OC-0000124429-2026 | AH39: 46100 | AI39: MEJ00199 | AJ39: UTP_Ica_Implementacion_tomacorrientes_mesas_biblioteca | AK39: 46055 | AL39: ESEVERINO | AM39: Logistica cambió codigo de proyecto a Generico, a solicitud de contabilidad
A40: 35 | B40: OPS_034 | C40: OPS | D40: Eloy / Raul | H40: Implementación de tomacorrientes para mesas de salas de estudio en biblioteca | I40: Se requiere habilitación de puntos eléctricos para 9 mesas, Se puede manejar internamente con área de mantenimiento, | J40: https://utpedupe-my,sharepoint,com/:f:/g/personal/grubio_utp_edu_pe/Emjzi9UGTElEiur-35Qm26UBtzTIdw9dPmfcLFeHzKzheg?e=MUMhXJ | K40: OK | L40: =SUM(M40:O40) -> 11 | M40: 4 | N40: 3 | O40: 4 | Q40: SI | R40: UTP Piura | S40: 70170101 | T40: UTP AV,PANAMERICANA 234 -PIURA | U40: 2500 | V40: 2183 | W40: A | X40: 46082 | Y40: 46172 | Z40: 46082 | AA40: 46127 | AB40: EJECUTADO | AC40: EJECUTADO | AD40: Proyectos Ops / Mantenimiento | AE40: SC-0000118063-2026 | AF40: 46073 | AG40: OC-0000123121-2026 | AH40: 46090 | AI40: MEJ00200 | AJ40: UTP_Piura_Implementacion_tomacorrientes_mesas_biblioteca | AK40: 46055 | AL40: ESEVERINO
A41: 36 | B41: OPS_035 | C41: OPS | D41: Eloy / Raul | H41: Implementación de tomacorrientes para mesas de salas de estudio en biblioteca | I41: Habilitación de puntos eléctricos para mesas de biblioteca 33 puntos | J41: Mesa de Estudios electrificada | K41: OK | L41: =SUM(M41:O41) -> 11 | M41: 4 | N41: 3 | O41: 4 | Q41: SI | R41: UTP Trujillo | S41: 70180103 | T41: UTP NICOLAS PIEROLA - TRUJILLO | U41: 17109 | V41: 17930.18 | W41: A | X41: 46143 | Y41: 46203 | Z41: 46143 | AA41: 46143 | AB41: EJECUTADO | AC41: EJECUTADO | AD41: Proyectos Ops / Mantenimiento | AE41: SC-0000117919-2026 | AF41: 46073 | AG41: OC-0000127316-2026 | AH41: 46134 | AI41: MEJ00201 | AJ41: UTP_Trujillo_Implementacion_tomacorrientes_mesas_biblioteca | AK41: 46055 | AL41: ESEVERINO
...

Sheet TD
A1: ESTADO | B1: (Todas)
A3: # | B3: Meses (FECHA FIN PLANIFICADA)
A4: CAMPUS | B4: <1/03/2026 | C4: Mar | D4: Abr | E4: May | F4: Jun | G4: Jul | H4: Ago | I4: Set | J4: Oct | K4: Nov | L4: Dic | M4: Total general
A5: UTP SJL | B5: =COUNTIFS(BD_INICIATIVAS!$R$7:$R$1000,$A5,BD_INICIATIVAS!$Y$7:$Y$1000,"<"&DATE(2026,3,1)) -> 0 | C5: =COUNTIFS(BD_INICIATIVAS!$R$7:$R$1000,$A5,BD_INICIATIVAS!$Y$7:$Y$1000,">="&DATE(2026,3,1),BD_INICIATIVAS!$Y$7:$Y$1000,"<"&DATE(2026,4,1)) -> 1 | D5: =COUNTIFS(BD_INICIATIVAS!$R$7:$R$1000,$A5,BD_INICIATIVAS!$Y$7:$Y$1000,">="&DATE(2026,4,1),BD_INICIATIVAS!$Y$7:$Y$1000,"<"&DATE(2026,5,1)) -> 0 | E5: =COUNTIFS(BD_INICIATIVAS!$R$7:$R$1000,$A5,BD_INICIATIVAS!$Y$7:$Y$1000,">="&DATE(2026,5,1),BD_INICIATIVAS!$Y$7:$Y$1000,"<"&DATE(2026,6,1)) -> 1 | F5: =COUNTIFS(BD_INICIATIVAS!$R$7:$R$1000,$A5,BD_INICIATIVAS!$Y$7:$Y$1000,">="&DATE(2026,6,1),BD_INICIATIVAS!$Y$7:$Y$1000,"<"&DATE(2026,7,1)) -> 1 | G5: =COUNTIFS(BD_INICIATIVAS!$R$7:$R$1000,$A5,BD_INICIATIVAS!$Y$7:$Y$1000,">="&DATE(2026,7,1),BD_INICIATIVAS!$Y$7:$Y$1000,"<"&DATE(2026,8,1)) -> 0 | H5: =COUNTIFS(BD_INICIATIVAS!$R$7:$R$1000,$A5,BD_INICIATIVAS!$Y$7:$Y$1000,">="&DATE(2026,8,1),BD_INICIATIVAS!$Y$7:$Y$1000,"<"&DATE(2026,9,1)) -> 3 | I5: =COUNTIFS(BD_INICIATIVAS!$R$7:$R$1000,$A5,BD_INICIATIVAS!$Y$7:$Y$1000,">="&DATE(2026,9,1),BD_INICIATIVAS!$Y$7:$Y$1000,"<"&DATE(2026,10,1)) -> 3 | J5: =COUNTIFS(BD_INICIATIVAS!$R$7:$R$1000,$A5,BD_INICIATIVAS!$Y$7:$Y$1000,">="&DATE(2026,10,1),BD_INICIATIVAS!$Y$7:$Y$1000,"<"&DATE(2026,11,1)) -> 1 | K5: =COUNTIFS(BD_INICIATIVAS!$R$7:$R$1000,$A5,BD_INICIATIVAS!$Y$7:$Y$1000,">="&DATE(2026,11,1),BD_INICIATIVAS!$Y$7:$Y$1000,"<"&DATE(2026,12,1)) -> 2 | L5: =COUNTIFS(BD_INICIATIVAS!$R$7:$R$1000,$A5,BD_INICIATIVAS!$Y$7:$Y$1000,">="&DATE(2026,12,1),BD_INICIATIVAS!$Y$7:$Y$1000,"<"&DATE(2027,1,1)) -> 1 | M5: =SUM(B5:L5) -> 13
A6: UTP Piura | B6: =COUNTIFS(BD_INICIATIVAS!$R$7:$R$1000,$A6,BD_INICIATIVAS!$Y$7:$Y$1000,"<"&DATE(2026,3,1)) -> 0 | C6: =COUNTIFS(BD_INICIATIVAS!$R$7:$R$1000,$A6,BD_INICIATIVAS!$Y$7:$Y$1000,">="&DATE(2026,3,1),BD_INICIATIVAS!$Y$7:$Y$1000,"<"&DATE(2026,4,1)) -> 2 | D6: =COUNTIFS(BD_INICIATIVAS!$R$7:$R$1000,$A6,BD_INICIATIVAS!$Y$7:$Y$1000,">="&DATE(2026,4,1),BD_INICIATIVAS!$Y$7:$Y$1000,"<"&DATE(2026,5,1)) -> 0 | E6: =COUNTIFS(BD_INICIATIVAS!$R$7:$R$1000,$A6,BD_INICIATIVAS!$Y$7:$Y$1000,">="&DATE(2026,5,1),BD_INICIATIVAS!$Y$7:$Y$1000,"<"&DATE(2026,6,1)) -> 2 | F6: =COUNTIFS(BD_INICIATIVAS!$R$7:$R$1000,$A6,BD_INICIATIVAS!$Y$7:$Y$1000,">="&DATE(2026,6,1),BD_INICIATIVAS!$Y$7:$Y$1000,"<"&DATE(2026,7,1)) -> 1 | G6: =COUNTIFS(BD_INICIATIVAS!$R$7:$R$1000,$A6,BD_INICIATIVAS!$Y$7:$Y$1000,">="&DATE(2026,7,1),BD_INICIATIVAS!$Y$7:$Y$1000,"<"&DATE(2026,8,1)) -> 0 | H6: =COUNTIFS(BD_INICIATIVAS!$R$7:$R$1000,$A6,BD_INICIATIVAS!$Y$7:$Y$1000,">="&DATE(2026,8,1),BD_INICIATIVAS!$Y$7:$Y$1000,"<"&DATE(2026,9,1)) -> 2 | I6: =COUNTIFS(BD_INICIATIVAS!$R$7:$R$1000,$A6,BD_INICIATIVAS!$Y$7:$Y$1000,">="&DATE(2026,9,1),BD_INICIATIVAS!$Y$7:$Y$1000,"<"&DATE(2026,10,1)) -> 0 | J6: =COUNTIFS(BD_INICIATIVAS!$R$7:$R$1000,$A6,BD_INICIATIVAS!$Y$7:$Y$1000,">="&DATE(2026,10,1),BD_INICIATIVAS!$Y$7:$Y$1000,"<"&DATE(2026,11,1)) -> 3 | K6: =COUNTIFS(BD_INICIATIVAS!$R$7:$R$1000,$A6,BD_INICIATIVAS!$Y$7:$Y$1000,">="&DATE(2026,11,1),BD_INICIATIVAS!$Y$7:$Y$1000,"<"&DATE(2026,12,1)) -> 3 | L6: =COUNTIFS(BD_INICIATIVAS!$R$7:$R$1000,$A6,BD_INICIATIVAS!$Y$7:$Y$1000,">="&DATE(2026,12,1),BD_INICIATIVAS!$Y$7:$Y$1000,"<"&DATE(2027,1,1)) -> 1 | M6: =SUM(B6:L6) -> 14
A7: UTP Trujillo | B7: =COUNTIFS(BD_INICIATIVAS!$R$7:$R$1000,$A7,BD_INICIATIVAS!$Y$7:$Y$1000,"<"&DATE(2026,3,1)) -> 0 | C7: =COUNTIFS(BD_INICIATIVAS!$R$7:$R$1000,$A7,BD_INICIATIVAS!$Y$7:$Y$1000,">="&DATE(2026,3,1),BD_INICIATIVAS!$Y$7:$Y$1000,"<"&DATE(2026,4,1)) -> 1 | D7: =COUNTIFS(BD_INICIATIVAS!$R$7:$R$1000,$A7,BD_INICIATIVAS!$Y$7:$Y$1000,">="&DATE(2026,4,1),BD_INICIATIVAS!$Y$7:$Y$1000,"<"&DATE(2026,5,1)) -> 0 | E7: =COUNTIFS(BD_INICIATIVAS!$R$7:$R$1000,$A7,BD_INICIATIVAS!$Y$7:$Y$1000,">="&DATE(2026,5,1),BD_INICIATIVAS!$Y$7:$Y$1000,"<"&DATE(2026,6,1)) -> 1 | F7: =COUNTIFS(BD_INICIATIVAS!$R$7:$R$1000,$A7,BD_INICIATIVAS!$Y$7:$Y$1000,">="&DATE(2026,6,1),BD_INICIATIVAS!$Y$7:$Y$1000,"<"&DATE(2026,7,1)) -> 2 | G7: =COUNTIFS(BD_INICIATIVAS!$R$7:$R$1000,$A7,BD_INICIATIVAS!$Y$7:$Y$1000,">="&DATE(2026,7,1),BD_INICIATIVAS!$Y$7:$Y$1000,"<"&DATE(2026,8,1)) -> 0 | H7: =COUNTIFS(BD_INICIATIVAS!$R$7:$R$1000,$A7,BD_INICIATIVAS!$Y$7:$Y$1000,">="&DATE(2026,8,1),BD_INICIATIVAS!$Y$7:$Y$1000,"<"&DATE(2026,9,1)) -> 3 | I7: =COUNTIFS(BD_INICIATIVAS!$R$7:$R$1000,$A7,BD_INICIATIVAS!$Y$7:$Y$1000,">="&DATE(2026,9,1),BD_INICIATIVAS!$Y$7:$Y$1000,"<"&DATE(2026,10,1)) -> 1 | J7: =COUNTIFS(BD_INICIATIVAS!$R$7:$R$1000,$A7,BD_INICIATIVAS!$Y$7:$Y$1000,">="&DATE(2026,10,1),BD_INICIATIVAS!$Y$7:$Y$1000,"<"&DATE(2026,11,1)) -> 1 | K7: =COUNTIFS(BD_INICIATIVAS!$R$7:$R$1000,$A7,BD_INICIATIVAS!$Y$7:$Y$1000,">="&DATE(2026,11,1),BD_INICIATIVAS!$Y$7:$Y$1000,"<"&DATE(2026,12,1)) -> 2 | L7: =COUNTIFS(BD_INICIATIVAS!$R$7:$R$1000,$A7,BD_INICIATIVAS!$Y$7:$Y$1000,">="&DATE(2026,12,1),BD_INICIATIVAS!$Y$7:$Y$1000,"<"&DATE(2027,1,1)) -> 1 | M7: =SUM(B7:L7) -> 12
A8: UTP Lima Norte | B8: =COUNTIFS(BD_INICIATIVAS!$R$7:$R$1000,$A8,BD_INICIATIVAS!$Y$7:$Y$1000,"<"&DATE(2026,3,1)) -> 0 | C8: =COUNTIFS(BD_INICIATIVAS!$R$7:$R$1000,$A8,BD_INICIATIVAS!$Y$7:$Y$1000,">="&DATE(2026,3,1),BD_INICIATIVAS!$Y$7:$Y$1000,"<"&DATE(2026,4,1)) -> 2 | D8: =COUNTIFS(BD_INICIATIVAS!$R$7:$R$1000,$A8,BD_INICIATIVAS!$Y$7:$Y$1000,">="&DATE(2026,4,1),BD_INICIATIVAS!$Y$7:$Y$1000,"<"&DATE(2026,5,1)) -> 0 | E8: =COUNTIFS(BD_INICIATIVAS!$R$7:$R$1000,$A8,BD_INICIATIVAS!$Y$7:$Y$1000,">="&DATE(2026,5,1),BD_INICIATIVAS!$Y$7:$Y$1000,"<"&DATE(2026,6,1)) -> 0 | F8: =COUNTIFS(BD_INICIATIVAS!$R$7:$R$1000,$A8,BD_INICIATIVAS!$Y$7:$Y$1000,">="&DATE(2026,6,1),BD_INICIATIVAS!$Y$7:$Y$1000,"<"&DATE(2026,7,1)) -> 1 | G8: =COUNTIFS(BD_INICIATIVAS!$R$7:$R$1000,$A8,BD_INICIATIVAS!$Y$7:$Y$1000,">="&DATE(2026,7,1),BD_INICIATIVAS!$Y$7:$Y$1000,"<"&DATE(2026,8,1)) -> 0 | H8: =COUNTIFS(BD_INICIATIVAS!$R$7:$R$1000,$A8,BD_INICIATIVAS!$Y$7:$Y$1000,">="&DATE(2026,8,1),BD_INICIATIVAS!$Y$7:$Y$1000,"<"&DATE(2026,9,1)) -> 1 | I8: =COUNTIFS(BD_INICIATIVAS!$R$7:$R$1000,$A8,BD_INICIATIVAS!$Y$7:$Y$1000,">="&DATE(2026,9,1),BD_INICIATIVAS!$Y$7:$Y$1000,"<"&DATE(2026,10,1)) -> 2 | J8: =COUNTIFS(BD_INICIATIVAS!$R$7:$R$1000,$A8,BD_INICIATIVAS!$Y$7:$Y$1000,">="&DATE(2026,10,1),BD_INICIATIVAS!$Y$7:$Y$1000,"<"&DATE(2026,11,1)) -> 2 | K8: =COUNTIFS(BD_INICIATIVAS!$R$7:$R$1000,$A8,BD_INICIATIVAS!$Y$7:$Y$1000,">="&DATE(2026,11,1),BD_INICIATIVAS!$Y$7:$Y$1000,"<"&DATE(2026,12,1)) -> 4 | L8: =COUNTIFS(BD_INICIATIVAS!$R$7:$R$1000,$A8,BD_INICIATIVAS!$Y$7:$Y$1000,">="&DATE(2026,12,1),BD_INICIATIVAS!$Y$7:$Y$1000,"<"&DATE(2027,1,1)) -> 1 | M8: =SUM(B8:L8) -> 13
A9: UTP Chimbote | B9: =COUNTIFS(BD_INICIATIVAS!$R$7:$R$1000,$A9,BD_INICIATIVAS!$Y$7:$Y$1000,"<"&DATE(2026,3,1)) -> 0 | C9: =COUNTIFS(BD_INICIATIVAS!$R$7:$R$1000,$A9,BD_INICIATIVAS!$Y$7:$Y$1000,">="&DATE(2026,3,1),BD_INICIATIVAS!$Y$7:$Y$1000,"<"&DATE(2026,4,1)) -> 1 | D9: =COUNTIFS(BD_INICIATIVAS!$R$7:$R$1000,$A9,BD_INICIATIVAS!$Y$7:$Y$1000,">="&DATE(2026,4,1),BD_INICIATIVAS!$Y$7:$Y$1000,"<"&DATE(2026,5,1)) -> 0 | E9: =COUNTIFS(BD_INICIATIVAS!$R$7:$R$1000,$A9,BD_INICIATIVAS!$Y$7:$Y$1000,">="&DATE(2026,5,1),BD_INICIATIVAS!$Y$7:$Y$1000,"<"&DATE(2026,6,1)) -> 1 | F9: =COUNTIFS(BD_INICIATIVAS!$R$7:$R$1000,$A9,BD_INICIATIVAS!$Y$7:$Y$1000,">="&DATE(2026,6,1),BD_INICIATIVAS!$Y$7:$Y$1000,"<"&DATE(2026,7,1)) -> 3 | G9: =COUNTIFS(BD_INICIATIVAS!$R$7:$R$1000,$A9,BD_INICIATIVAS!$Y$7:$Y$1000,">="&DATE(2026,7,1),BD_INICIATIVAS!$Y$7:$Y$1000,"<"&DATE(2026,8,1)) -> 0 | H9: =COUNTIFS(BD_INICIATIVAS!$R$7:$R$1000,$A9,BD_INICIATIVAS!$Y$7:$Y$1000,">="&DATE(2026,8,1),BD_INICIATIVAS!$Y$7:$Y$1000,"<"&DATE(2026,9,1)) -> 2 | I9: =COUNTIFS(BD_INICIATIVAS!$R$7:$R$1000,$A9,BD_INICIATIVAS!$Y$7:$Y$1000,">="&DATE(2026,9,1),BD_INICIATIVAS!$Y$7:$Y$1000,"<"&DATE(2026,10,1)) -> 0 | J9: =COUNTIFS(BD_INICIATIVAS!$R$7:$R$1000,$A9,BD_INICIATIVAS!$Y$7:$Y$1000,">="&DATE(2026,10,1),BD_INICIATIVAS!$Y$7:$Y$1000,"<"&DATE(2026,11,1)) -> 1 | K9: =COUNTIFS(BD_INICIATIVAS!$R$7:$R$1000,$A9,BD_INICIATIVAS!$Y$7:$Y$1000,">="&DATE(2026,11,1),BD_INICIATIVAS!$Y$7:$Y$1000,"<"&DATE(2026,12,1)) -> 2 | L9: =COUNTIFS(BD_INICIATIVAS!$R$7:$R$1000,$A9,BD_INICIATIVAS!$Y$7:$Y$1000,">="&DATE(2026,12,1),BD_INICIATIVAS!$Y$7:$Y$1000,"<"&DATE(2027,1,1)) -> 1 | M9: =SUM(B9:L9) -> 11
A10: UTP Lima Centro | B10: =COUNTIFS(BD_INICIATIVAS!$R$7:$R$1000,$A10,BD_INICIATIVAS!$Y$7:$Y$1000,"<"&DATE(2026,3,1)) -> 0 | C10: =COUNTIFS(BD_INICIATIVAS!$R$7:$R$1000,$A10,BD_INICIATIVAS!$Y$7:$Y$1000,">="&DATE(2026,3,1),BD_INICIATIVAS!$Y$7:$Y$1000,"<"&DATE(2026,4,1)) -> 7 | D10: =COUNTIFS(BD_INICIATIVAS!$R$7:$R$1000,$A10,BD_INICIATIVAS!$Y$7:$Y$1000,">="&DATE(2026,4,1),BD_INICIATIVAS!$Y$7:$Y$1000,"<"&DATE(2026,5,1)) -> 1 | E10: =COUNTIFS(BD_INICIATIVAS!$R$7:$R$1000,$A10,BD_INICIATIVAS!$Y$7:$Y$1000,">="&DATE(2026,5,1),BD_INICIATIVAS!$Y$7:$Y$1000,"<"&DATE(2026,6,1)) -> 6 | F10: =COUNTIFS(BD_INICIATIVAS!$R$7:$R$1000,$A10,BD_INICIATIVAS!$Y$7:$Y$1000,">="&DATE(2026,6,1),BD_INICIATIVAS!$Y$7:$Y$1000,"<"&DATE(2026,7,1)) -> 5 | G10: =COUNTIFS(BD_INICIATIVAS!$R$7:$R$1000,$A10,BD_INICIATIVAS!$Y$7:$Y$1000,">="&DATE(2026,7,1),BD_INICIATIVAS!$Y$7:$Y$1000,"<"&DATE(2026,8,1)) -> 3 | H10: =COUNTIFS(BD_INICIATIVAS!$R$7:$R$1000,$A10,BD_INICIATIVAS!$Y$7:$Y$1000,">="&DATE(2026,8,1),BD_INICIATIVAS!$Y$7:$Y$1000,"<"&DATE(2026,9,1)) -> 12 | I10: =COUNTIFS(BD_INICIATIVAS!$R$7:$R$1000,$A10,BD_INICIATIVAS!$Y$7:$Y$1000,">="&DATE(2026,9,1),BD_INICIATIVAS!$Y$7:$Y$1000,"<"&DATE(2026,10,1)) -> 5 | J10: =COUNTIFS(BD_INICIATIVAS!$R$7:$R$1000,$A10,BD_INICIATIVAS!$Y$7:$Y$1000,">="&DATE(2026,10,1),BD_INICIATIVAS!$Y$7:$Y$1000,"<"&DATE(2026,11,1)) -> 10 | K10: =COUNTIFS(BD_INICIATIVAS!$R$7:$R$1000,$A10,BD_INICIATIVAS!$Y$7:$Y$1000,">="&DATE(2026,11,1),BD_INICIATIVAS!$Y$7:$Y$1000,"<"&DATE(2026,12,1)) -> 10 | L10: =COUNTIFS(BD_INICIATIVAS!$R$7:$R$1000,$A10,BD_INICIATIVAS!$Y$7:$Y$1000,">="&DATE(2026,12,1),BD_INICIATIVAS!$Y$7:$Y$1000,"<"&DATE(2027,1,1)) -> 4 | M10: =SUM(B10:L10) -> 63
